[2025-07-08T21:32:37.124+0000] {taskinstance.py:1956} INFO - Dependencies all met for dep_context=non-requeueable deps ti=<TaskInstance: products_sales_report.transform_data manual__2025-07-08T21:31:57.241891+00:00 [queued]>
[2025-07-08T21:32:37.140+0000] {taskinstance.py:1956} INFO - Dependencies all met for dep_context=requeueable deps ti=<TaskInstance: products_sales_report.transform_data manual__2025-07-08T21:31:57.241891+00:00 [queued]>
[2025-07-08T21:32:37.141+0000] {taskinstance.py:2170} INFO - Starting attempt 1 of 1
[2025-07-08T21:32:37.167+0000] {taskinstance.py:2191} INFO - Executing <Task(PythonOperator): transform_data> on 2025-07-08 21:31:57.241891+00:00
[2025-07-08T21:32:37.179+0000] {standard_task_runner.py:60} INFO - Started process 1127 to run task
[2025-07-08T21:32:37.186+0000] {standard_task_runner.py:87} INFO - Running: ['***', 'tasks', 'run', 'products_sales_report', 'transform_data', 'manual__2025-07-08T21:31:57.241891+00:00', '--job-id', '16', '--raw', '--subdir', 'DAGS_FOLDER/products_sales_report.py', '--cfg-path', '/tmp/tmp07hjds96']
[2025-07-08T21:32:37.188+0000] {standard_task_runner.py:88} INFO - Job 16: Subtask transform_data
[2025-07-08T21:32:37.271+0000] {task_command.py:423} INFO - Running <TaskInstance: products_sales_report.transform_data manual__2025-07-08T21:31:57.241891+00:00 [running]> on host 32522fb872a4
[2025-07-08T21:32:37.406+0000] {taskinstance.py:2480} INFO - Exporting env vars: AIRFLOW_CTX_DAG_OWNER='***' AIRFLOW_CTX_DAG_ID='products_sales_report' AIRFLOW_CTX_TASK_ID='transform_data' AIRFLOW_CTX_EXECUTION_DATE='2025-07-08T21:31:57.241891+00:00' AIRFLOW_CTX_TRY_NUMBER='1' AIRFLOW_CTX_DAG_RUN_ID='manual__2025-07-08T21:31:57.241891+00:00'
[2025-07-08T21:32:37.474+0000] {taskinstance.py:2698} ERROR - Task failed with exception
Traceback (most recent call last):
  File "/home/airflow/.local/lib/python3.8/site-packages/pandas/core/indexes/base.py", line 3653, in get_loc
    return self._engine.get_loc(casted_key)
  File "pandas/_libs/index.pyx", line 147, in pandas._libs.index.IndexEngine.get_loc
  File "pandas/_libs/index.pyx", line 176, in pandas._libs.index.IndexEngine.get_loc
  File "pandas/_libs/hashtable_class_helper.pxi", line 7080, in pandas._libs.hashtable.PyObjectHashTable.get_item
  File "pandas/_libs/hashtable_class_helper.pxi", line 7088, in pandas._libs.hashtable.PyObjectHashTable.get_item
KeyError: 'date'

The above exception was the direct cause of the following exception:

Traceback (most recent call last):
  File "/home/airflow/.local/lib/python3.8/site-packages/airflow/models/taskinstance.py", line 433, in _execute_task
    result = execute_callable(context=context, **execute_callable_kwargs)
  File "/home/airflow/.local/lib/python3.8/site-packages/airflow/operators/python.py", line 199, in execute
    return_value = self.execute_callable()
  File "/home/airflow/.local/lib/python3.8/site-packages/airflow/operators/python.py", line 216, in execute_callable
    return self.python_callable(*self.op_args, **self.op_kwargs)
  File "/opt/airflow/dags/products_sales_report.py", line 23, in transform_data
    df['date'] = pd.to_datetime(df['date'])
  File "/home/airflow/.local/lib/python3.8/site-packages/pandas/core/frame.py", line 3761, in __getitem__
    indexer = self.columns.get_loc(key)
  File "/home/airflow/.local/lib/python3.8/site-packages/pandas/core/indexes/base.py", line 3655, in get_loc
    raise KeyError(key) from err
KeyError: 'date'
[2025-07-08T21:32:37.508+0000] {taskinstance.py:1138} INFO - Marking task as FAILED. dag_id=products_sales_report, task_id=transform_data, execution_date=20250708T213157, start_date=20250708T213237, end_date=20250708T213237
[2025-07-08T21:32:37.535+0000] {standard_task_runner.py:107} ERROR - Failed to execute job 16 for task transform_data ('date'; 1127)
[2025-07-08T21:32:37.559+0000] {local_task_job_runner.py:234} INFO - Task exited with return code 1
[2025-07-08T21:32:37.595+0000] {taskinstance.py:3280} INFO - 0 downstream tasks scheduled from follow-on schedule check
