[2025-07-08T21:56:14.776+0000] {taskinstance.py:1956} INFO - Dependencies all met for dep_context=non-requeueable deps ti=<TaskInstance: products_sales_report.save_to_file manual__2025-07-08T21:55:22.015315+00:00 [queued]>
[2025-07-08T21:56:14.792+0000] {taskinstance.py:1956} INFO - Dependencies all met for dep_context=requeueable deps ti=<TaskInstance: products_sales_report.save_to_file manual__2025-07-08T21:55:22.015315+00:00 [queued]>
[2025-07-08T21:56:14.793+0000] {taskinstance.py:2170} INFO - Starting attempt 1 of 1
[2025-07-08T21:56:14.825+0000] {taskinstance.py:2191} INFO - Executing <Task(PythonOperator): save_to_file> on 2025-07-08 21:55:22.015315+00:00
[2025-07-08T21:56:14.836+0000] {standard_task_runner.py:60} INFO - Started process 1408 to run task
[2025-07-08T21:56:14.842+0000] {standard_task_runner.py:87} INFO - Running: ['***', 'tasks', 'run', 'products_sales_report', 'save_to_file', 'manual__2025-07-08T21:55:22.015315+00:00', '--job-id', '21', '--raw', '--subdir', 'DAGS_FOLDER/products_sales_report.py', '--cfg-path', '/tmp/tmphp_arv_9']
[2025-07-08T21:56:14.844+0000] {standard_task_runner.py:88} INFO - Job 21: Subtask save_to_file
[2025-07-08T21:56:14.971+0000] {task_command.py:423} INFO - Running <TaskInstance: products_sales_report.save_to_file manual__2025-07-08T21:55:22.015315+00:00 [running]> on host 32522fb872a4
[2025-07-08T21:56:15.267+0000] {taskinstance.py:2480} INFO - Exporting env vars: AIRFLOW_CTX_DAG_OWNER='***' AIRFLOW_CTX_DAG_ID='products_sales_report' AIRFLOW_CTX_TASK_ID='save_to_file' AIRFLOW_CTX_EXECUTION_DATE='2025-07-08T21:55:22.015315+00:00' AIRFLOW_CTX_TRY_NUMBER='1' AIRFLOW_CTX_DAG_RUN_ID='manual__2025-07-08T21:55:22.015315+00:00'
[2025-07-08T21:56:15.618+0000] {taskinstance.py:2698} ERROR - Task failed with exception
Traceback (most recent call last):
  File "/home/airflow/.local/lib/python3.8/site-packages/airflow/models/taskinstance.py", line 433, in _execute_task
    result = execute_callable(context=context, **execute_callable_kwargs)
  File "/home/airflow/.local/lib/python3.8/site-packages/airflow/operators/python.py", line 199, in execute
    return_value = self.execute_callable()
  File "/home/airflow/.local/lib/python3.8/site-packages/airflow/operators/python.py", line 216, in execute_callable
    return self.python_callable(*self.op_args, **self.op_kwargs)
  File "/opt/airflow/dags/products_sales_report.py", line 41, in save_to_file
    summary_df.to_csv('/opt/airflow/files/sales_summary.csv', index=False)
  File "/home/airflow/.local/lib/python3.8/site-packages/pandas/core/generic.py", line 3772, in to_csv
    return DataFrameRenderer(formatter).to_csv(
  File "/home/airflow/.local/lib/python3.8/site-packages/pandas/io/formats/format.py", line 1186, in to_csv
    csv_formatter.save()
  File "/home/airflow/.local/lib/python3.8/site-packages/pandas/io/formats/csvs.py", line 240, in save
    with get_handle(
  File "/home/airflow/.local/lib/python3.8/site-packages/pandas/io/common.py", line 737, in get_handle
    check_parent_directory(str(handle))
  File "/home/airflow/.local/lib/python3.8/site-packages/pandas/io/common.py", line 600, in check_parent_directory
    raise OSError(rf"Cannot save file into a non-existent directory: '{parent}'")
OSError: Cannot save file into a non-existent directory: '/opt/***/files'
[2025-07-08T21:56:15.696+0000] {taskinstance.py:1138} INFO - Marking task as FAILED. dag_id=products_sales_report, task_id=save_to_file, execution_date=20250708T215522, start_date=20250708T215614, end_date=20250708T215615
[2025-07-08T21:56:15.765+0000] {standard_task_runner.py:107} ERROR - Failed to execute job 21 for task save_to_file (Cannot save file into a non-existent directory: '/opt/***/files'; 1408)
[2025-07-08T21:56:15.824+0000] {local_task_job_runner.py:234} INFO - Task exited with return code 1
[2025-07-08T21:56:15.906+0000] {taskinstance.py:3280} INFO - 0 downstream tasks scheduled from follow-on schedule check
