[2025-07-08T21:28:46.757+0000] {taskinstance.py:1956} INFO - Dependencies all met for dep_context=non-requeueable deps ti=<TaskInstance: products_sales_report.fetch_data manual__2025-07-08T21:28:13.621086+00:00 [queued]>
[2025-07-08T21:28:46.779+0000] {taskinstance.py:1956} INFO - Dependencies all met for dep_context=requeueable deps ti=<TaskInstance: products_sales_report.fetch_data manual__2025-07-08T21:28:13.621086+00:00 [queued]>
[2025-07-08T21:28:46.784+0000] {taskinstance.py:2170} INFO - Starting attempt 1 of 1
[2025-07-08T21:28:46.825+0000] {taskinstance.py:2191} INFO - Executing <Task(PythonOperator): fetch_data> on 2025-07-08 21:28:13.621086+00:00
[2025-07-08T21:28:46.841+0000] {standard_task_runner.py:60} INFO - Started process 1081 to run task
[2025-07-08T21:28:46.850+0000] {standard_task_runner.py:87} INFO - Running: ['***', 'tasks', 'run', 'products_sales_report', 'fetch_data', 'manual__2025-07-08T21:28:13.621086+00:00', '--job-id', '14', '--raw', '--subdir', 'DAGS_FOLDER/products_sales_report.py', '--cfg-path', '/tmp/tmpbs9_9c8z']
[2025-07-08T21:28:46.854+0000] {standard_task_runner.py:88} INFO - Job 14: Subtask fetch_data
[2025-07-08T21:28:46.964+0000] {task_command.py:423} INFO - Running <TaskInstance: products_sales_report.fetch_data manual__2025-07-08T21:28:13.621086+00:00 [running]> on host 32522fb872a4
[2025-07-08T21:28:47.173+0000] {taskinstance.py:2480} INFO - Exporting env vars: AIRFLOW_CTX_DAG_OWNER='***' AIRFLOW_CTX_DAG_ID='products_sales_report' AIRFLOW_CTX_TASK_ID='fetch_data' AIRFLOW_CTX_EXECUTION_DATE='2025-07-08T21:28:13.621086+00:00' AIRFLOW_CTX_TRY_NUMBER='1' AIRFLOW_CTX_DAG_RUN_ID='manual__2025-07-08T21:28:13.621086+00:00'
[2025-07-08T21:28:47.944+0000] {taskinstance.py:2698} ERROR - Task failed with exception
Traceback (most recent call last):
  File "/home/airflow/.local/lib/python3.8/site-packages/urllib3/connection.py", line 174, in _new_conn
    conn = connection.create_connection(
  File "/home/airflow/.local/lib/python3.8/site-packages/urllib3/util/connection.py", line 72, in create_connection
    for res in socket.getaddrinfo(host, port, family, socket.SOCK_STREAM):
  File "/usr/local/lib/python3.8/socket.py", line 918, in getaddrinfo
    for res in _socket.getaddrinfo(host, port, family, type, proto, flags):
socket.gaierror: [Errno -2] Name or service not known

During handling of the above exception, another exception occurred:

Traceback (most recent call last):
  File "/home/airflow/.local/lib/python3.8/site-packages/urllib3/connectionpool.py", line 715, in urlopen
    httplib_response = self._make_request(
  File "/home/airflow/.local/lib/python3.8/site-packages/urllib3/connectionpool.py", line 404, in _make_request
    self._validate_conn(conn)
  File "/home/airflow/.local/lib/python3.8/site-packages/urllib3/connectionpool.py", line 1058, in _validate_conn
    conn.connect()
  File "/home/airflow/.local/lib/python3.8/site-packages/urllib3/connection.py", line 363, in connect
    self.sock = conn = self._new_conn()
  File "/home/airflow/.local/lib/python3.8/site-packages/urllib3/connection.py", line 186, in _new_conn
    raise NewConnectionError(
urllib3.exceptions.NewConnectionError: <urllib3.connection.HTTPSConnection object at 0x7f67a2711c10>: Failed to establish a new connection: [Errno -2] Name or service not known

During handling of the above exception, another exception occurred:

Traceback (most recent call last):
  File "/home/airflow/.local/lib/python3.8/site-packages/requests/adapters.py", line 486, in send
    resp = conn.urlopen(
  File "/home/airflow/.local/lib/python3.8/site-packages/urllib3/connectionpool.py", line 799, in urlopen
    retries = retries.increment(
  File "/home/airflow/.local/lib/python3.8/site-packages/urllib3/util/retry.py", line 592, in increment
    raise MaxRetryError(_pool, url, error or ResponseError(cause))
urllib3.exceptions.MaxRetryError: HTTPSConnectionPool(host='api.example.com', port=443): Max retries exceeded with url: /sales (Caused by NewConnectionError('<urllib3.connection.HTTPSConnection object at 0x7f67a2711c10>: Failed to establish a new connection: [Errno -2] Name or service not known'))

During handling of the above exception, another exception occurred:

Traceback (most recent call last):
  File "/home/airflow/.local/lib/python3.8/site-packages/airflow/models/taskinstance.py", line 433, in _execute_task
    result = execute_callable(context=context, **execute_callable_kwargs)
  File "/home/airflow/.local/lib/python3.8/site-packages/airflow/operators/python.py", line 199, in execute
    return_value = self.execute_callable()
  File "/home/airflow/.local/lib/python3.8/site-packages/airflow/operators/python.py", line 216, in execute_callable
    return self.python_callable(*self.op_args, **self.op_kwargs)
  File "/opt/airflow/dags/products_sales_report.py", line 10, in fetch_data
    response = requests.get(url)
  File "/home/airflow/.local/lib/python3.8/site-packages/requests/api.py", line 73, in get
    return request("get", url, params=params, **kwargs)
  File "/home/airflow/.local/lib/python3.8/site-packages/requests/api.py", line 59, in request
    return session.request(method=method, url=url, **kwargs)
  File "/home/airflow/.local/lib/python3.8/site-packages/requests/sessions.py", line 589, in request
    resp = self.send(prep, **send_kwargs)
  File "/home/airflow/.local/lib/python3.8/site-packages/requests/sessions.py", line 703, in send
    r = adapter.send(request, **kwargs)
  File "/home/airflow/.local/lib/python3.8/site-packages/requests/adapters.py", line 519, in send
    raise ConnectionError(e, request=request)
requests.exceptions.ConnectionError: HTTPSConnectionPool(host='api.example.com', port=443): Max retries exceeded with url: /sales (Caused by NewConnectionError('<urllib3.connection.HTTPSConnection object at 0x7f67a2711c10>: Failed to establish a new connection: [Errno -2] Name or service not known'))
[2025-07-08T21:28:48.001+0000] {taskinstance.py:1138} INFO - Marking task as FAILED. dag_id=products_sales_report, task_id=fetch_data, execution_date=20250708T212813, start_date=20250708T212846, end_date=20250708T212848
[2025-07-08T21:28:48.043+0000] {standard_task_runner.py:107} ERROR - Failed to execute job 14 for task fetch_data (HTTPSConnectionPool(host='api.example.com', port=443): Max retries exceeded with url: /sales (Caused by NewConnectionError('<urllib3.connection.HTTPSConnection object at 0x7f67a2711c10>: Failed to establish a new connection: [Errno -2] Name or service not known')); 1081)
[2025-07-08T21:28:48.077+0000] {local_task_job_runner.py:234} INFO - Task exited with return code 1
[2025-07-08T21:28:48.157+0000] {taskinstance.py:3280} INFO - 0 downstream tasks scheduled from follow-on schedule check
